Workbook

Sheet Sheet1
A1: Timestamp | B1: Sample prefix | C1: Sample number | D1: Sample_name_desc | E1: Collector | F1: Broad-scope substrate | G1: Lat-Long | H1: Sample description | I1: Item (sink, toilet, P-trap, etc.) | J1: Volume | K1: Column 9 | L1: Sample description | M1: Flow rate (LPM) | N1: Sampling time (min) | O1: Sample description | P1: Plant species | Q1: Sampling method | R1: Organs sampled | S1: Site description | T1: Sampling method | U1: Sampling area (cm^2) | V1: Substrate description | W1: Substrate description | X1: Depth minimum (cm) | Y1: Depth maximum (cm) | Z1: Vegetation | AA1: Material | AB1: SourceSink | AC1: SourceSinkID
A2: 45674.692 | B2: NC25 | C2: 9 | D2: GLF_DOWNSTRM_GRASS-1 | E2: Julian Liber | F2: Plant | G2: 35.6232978, -82.3304456 | P2: Turf grass | Q2: Material in tube | R2: Leaves | S2: Lawn, 3m from creek, South of building | AA2: Plant | AB2: Source | AC2: {=VLOOKUP(INDEX(_xlfn.TEXTSPLIT(D2, "_"), 1), Sheet2!A$1:B$3, 2, FALSE)} -> 2
A3: 45674.624 | B3: NC25 | C3: 11 | D3: PW_RIVERPROX_HERB-1 | E3: Julian Liber | F3: Plant | G3: 35°36′44″ N 82°19′16″ W | P3: Hairy bitter cress | Q3: Material in tube | R3: Leaves | S3: Near building public works, near river | AA3: Plant | AB3: Source | AC3: {=VLOOKUP(INDEX(_xlfn.TEXTSPLIT(D3, "_"), 1), Sheet2!A$1:B$3, 2, FALSE)} -> 1
A4: 45674.74 | B4: NC25 | C4: 12 | D4: VP_FLOOD_SHRUB-1 | E4: Julian Liber | F4: Plant | G4: 35.6074252, -82.3381415 | P4: Lonicera sp | Q4: Material in tube | R4: Leaves | S4: Fence, likely flooded | AA4: Plant | AB4: Source | AC4: {=VLOOKUP(INDEX(_xlfn.TEXTSPLIT(D4, "_"), 1), Sheet2!A$1:B$3, 2, FALSE)} -> 3
A5: 45674.598 | B5: NC25 | C5: 14 | D5: PW_HILLSIDE_HERB-1 | E5: Julian Liber | F5: Plant | G5: 35°36′48″ N 82°19′15″ W | P5: White clover | Q5: Material in tube | R5: Leaves | S5: Side of public works | AA5: Plant | AB5: Source | AC5: {=VLOOKUP(INDEX(_xlfn.TEXTSPLIT(D5, "_"), 1), Sheet2!A$1:B$3, 2, FALSE)} -> 1
A6: 45674.694 | B6: NC25 | C6: 15 | D6: GLF_DWNSTRM_RIVERDIST_3M_HERB-1 | E6: Julian Liber | F6: Plant | G6: 35.6232978, -82.3304456 | P6: Glechoma hederacea | Q6: Material in tube | R6: Leaves | S6: Lawn, 3m from creek, south of building | AA6: Plant | AB6: Source | AC6: {=VLOOKUP(INDEX(_xlfn.TEXTSPLIT(D6, "_"), 1), Sheet2!A$1:B$3, 2, FALSE)} -> 2
A7: 45674.738 | B7: NC25 | C7: 17 | D7: VP_FLOOD_HERB-1 | E7: Julian Liber | F7: Plant | G7: 35.6074252, -82.3381415 | P7: English ivy | Q7: Material in tube | R7: Leaves | S7: On ground, flooded | AA7: Plant | AB7: Source | AC7: {=VLOOKUP(INDEX(_xlfn.TEXTSPLIT(D7, "_"), 1), Sheet2!A$1:B$3, 2, FALSE)} -> 3
A8: 45674.685 | B8: NC25 | C8: 18 | D8: GLF_RIVERDIST_45M_HERB-1 | E8: Julian Liber | F8: Plant | G8: 35.6236532, -82.3301469 | P8: White clover | Q8: Material in tube | R8: Leaves | S8: Lawn, 45m from creek, low area with sediment | AA8: Plant | AB8: Source | AC8: {=VLOOKUP(INDEX(_xlfn.TEXTSPLIT(D8, "_"), 1), Sheet2!A$1:B$3, 2, FALSE)} -> 2
A9: 45674.686 | B9: NC25 | C9: 19 | D9: GLF_RIVERDIST_45M_GRASS-1 | E9: Julian Liber | F9: Plant | G9: 35.6236532, -82.3301469 | P9: Turf grass | Q9: Material in tube | R9: Leaves | S9: Lawn, 45m from creek, low area with sediment | AA9: Plant | AB9: Source | AC9: {=VLOOKUP(INDEX(_xlfn.TEXTSPLIT(D9, "_"), 1), Sheet2!A$1:B$3, 2, FALSE)} -> 2
A10: 45674.673 | B10: NC25 | C10: 22 | D10: GLF_UPSTRM_RIVERDIST_4M_GRASS-1 | E10: Julian Liber | F10: Plant | G10: 35.6237870, -82.3307132 | P10: Turf grass | Q10: Material in tube | R10: Leaves | S10: ~4 m from creek, North of the building | AA10: Plant | AB10: Source | AC10: {=VLOOKUP(INDEX(_xlfn.TEXTSPLIT(D10, "_"), 1), Sheet2!A$1:B$3, 2, FALSE)} -> 2
A11: 45674.737 | B11: NC25 | C11: 66 | D11: VP_DRY_HERB-1 | E11: Julian Liber | F11: Plant | G11: 35.6074252, -82.3381415 | P11: English ivy | Q11: Material in tube | R11: Leaves | S11: On tree, 6ft off ground | AA11: Plant | AB11: Source | AC11: {=VLOOKUP(INDEX(_xlfn.TEXTSPLIT(D11, "_"), 1), Sheet2!A$1:B$3, 2, FALSE)} -> 3
A12: 45674.677 | B12: NC25 | C12: 69 | D12: GLF_UPSTRM_RIVERDIST_HERB-1 | E12: Julian Liber | F12: Plant | G12: 35.6238576, -82.3304302 | P12: White clover | Q12: Material in tube | R12: Leaves | S12: Lawn, 15m from creek | AA12: Plant | AB12: Source | AC12: {=VLOOKUP(INDEX(_xlfn.TEXTSPLIT(D12, "_"), 1), Sheet2!A$1:B$3, 2, FALSE)} -> 2
A13: 45674.744 | B13: NC25 | C13: 70 | D13: VP_DWNSTRM_HERB-1 | E13: Julian Liber | F13: Plant | G13: 35.6078927, -82.3382391 | P13: Hairy bittercress | Q13: Material in tube | R13: Leaves | S13: Flooded, next to ditch, adjacent to parking lot and baseball fields | AA13: Plant | AB13: Source | AC13: {=VLOOKUP(INDEX(_xlfn.TEXTSPLIT(D13, "_"), 1), Sheet2!A$1:B$3, 2, FALSE)} -> 3
... A17: 45674.68 | B17: NC25 | C17: 81 | D17: GLF_RIVERDIST_85M_HERB-1 | E17: Julian Liber | F17: Plant | G17: 35.6239652, -82.3298471 | P17: medicago | Q17: Material in tube | R17: Leaves | S17: Lawn, 80m from creek | AA17: Plant | AB17: Source | AC17: {=VLOOKUP(INDEX(_xlfn.TEXTSPLIT(D17, "_"), 1), Sheet2!A$1:B$3, 2, FALSE)} -> 2
A18: 45674.662 | B18: NC25 | C18: 86 | D18: PW_DRYWALL_INNER-1 | E18: Vesper Fraunfelter | F18: Built surface | G18: 35°36′46.8″N, 82°19′13″W | T18: Swab | V18: Dry wall (inner) | AA18: Drywall | AB18: Sink | AC18: {=VLOOKUP(INDEX(_xlfn.TEXTSPLIT(D18, "_"), 1), Sheet2!A$1:B$3, 2, FALSE)} -> 1
A19: 45674.663 | B19: NC25 | C19: 87 | D19: PW_DRYWALL_ADHESIVE-1 | E19: Vesper Fraunfelter | F19: Built surface | G19: 35°36′46.8″N, 82°19′13″W | T19: Swab | V19: Drywall-insulation adhesive | AA19: Drywall | AB19: Sink | AC19: {=VLOOKUP(INDEX(_xlfn.TEXTSPLIT(D19, "_"), 1), Sheet2!A$1:B$3, 2, FALSE)} -> 1
A20: 45674.664 | B20: NC25 | C20: 88 | D20: PW_CONCRETE_FLOOD-1 | E20: Vesper Fraunfelter | F20: Built surface | G20: 35°36′46.8″N, 82°19′13″W | T20: Swab | V20: Concrete (ground) | AA20: Concrete | AB20: Sink | AC20: {=VLOOKUP(INDEX(_xlfn.TEXTSPLIT(D20, "_"), 1), Sheet2!A$1:B$3, 2, FALSE)} -> 1
A21: 45674.664 | B21: NC25 | C21: 89 | D21: PW_METAL_FLOOD-1 | E21: Vesper Fraunfelter | F21: Built surface | G21: 35°36′46.8″N, 82°19′13″W | T21: Swab | V21: Metal (flooded) | AA21: Metal | AB21: Sink | AC21: {=VLOOKUP(INDEX(_xlfn.TEXTSPLIT(D21, "_"), 1), Sheet2!A$1:B$3, 2, FALSE)} -> 1
A22: 45674.665 | B22: NC25 | C22: 90 | D22: PW_PLASTIC_FLOOD-1 | E22: Vesper Fraunfelter | F22: Built surface | G22: 35°36′47″N, 82°19′14.4″W | T22: Swab | V22: Dust on plastic bin | AA22: Plastic | AB22: Sink | AC22: {=VLOOKUP(INDEX(_xlfn.TEXTSPLIT(D22, "_"), 1), Sheet2!A$1:B$3, 2, FALSE)} -> 1
A23: 45674.666 | B23: NC25 | C23: 91 | D23: PW_METAL_FLOOD-2 | E23: Vesper Fraunfelter | F23: Built surface | G23: 35°36′48.8″N, 82°19′15.3″W | T23: Swab | V23: Metal studs with coloration | AA23: Metal | AB23: Sink | AC23: {=VLOOKUP(INDEX(_xlfn.TEXTSPLIT(D23, "_"), 1), Sheet2!A$1:B$3, 2, FALSE)} -> 1
A24: 45674.666 | B24: NC25 | C24: 92 | D24: PW_CONCRETE_FLOOD-2 | E24: Vesper Fraunfelter | F24: Built surface | G24: 35°36′48.1″N, 82°19′15.1″W | T24: Swab | U24: Small | V24: Concrete between metal walls | AA24: Concrete | AB24: Sink | AC24: {=VLOOKUP(INDEX(_xlfn.TEXTSPLIT(D24, "_"), 1), Sheet2!A$1:B$3, 2, FALSE)} -> 1
A25: 45674.77 | B25: NC25 | C25: 93 | D25: PW_WOOD_CLEANED-1 | E25: Vesper Fraunfelter | F25: Built surface | G25: 35°36′47.2″N, 82°19′15.4″W | T25: Swab | V25: Coloration on cleaned wood | AA25: Wood | AB25: Sink | AC25: {=VLOOKUP(INDEX(_xlfn.TEXTSPLIT(D25, "_"), 1), Sheet2!A$1:B$3, 2, FALSE)} -> 1
A26: 45674.616 | B26: NC25 | C26: 94 | D26: PW_PORCEL_SINK-1 | E26: Andrew Jones | F26: Built surface | G26: 35°36′49″ N 82°19′12″ W | T26: Swab | V26: Men’s restroom sink right | AA26: Ceramic | AB26: Sink | AC26: {=VLOOKUP(INDEX(_xlfn.TEXTSPLIT(D26, "_"), 1), Sheet2!A$1:B$3, 2, FALSE)} -> 1
A27: 45674.772 | B27: NC25 | C27: 96 | D27: PW_PVC_DRAIN_OUTER-1 | E27: Vesper Fraunfelter | F27: Built surface | G27: 35°36′47.7″N, 82°19′12.8″W | T27: Swab | V27: PVC toilet drain (outer) | AA27: Plastic | AB27: Sink | AC27: {=VLOOKUP(INDEX(_xlfn.TEXTSPLIT(D27, "_"), 1), Sheet2!A$1:B$3, 2, FALSE)} -> 1
A28: 45674.773 | B28: NC25 | C28: 97 | D28: PW_WOOD_SINK-1 | E28: Vesper Fraunfelter | F28: Built surface | G28: 35°36′47.7″N, 82°19′12.8″W | T28: Swab | V28: Bathroom sink frame (wood) | AA28: Wood | AB28: Sink | AC28: {=VLOOKUP(INDEX(_xlfn.TEXTSPLIT(D28, "_"), 1), Sheet2!A$1:B$3, 2, FALSE)} -> 1
A29: 45674.775 | B29: NC25 | C29: 98 | D29: PW_PLASTIC_FLOOD-2 | E29: Vesper Fraunfelter | F29: Built surface | G29: 35°36′47.2″N, 82°19′13.2″W | T29: Swab | V29: Mop basin (plastic?) | AA29: Plastic | AB29: Sink | AC29: {=VLOOKUP(INDEX(_xlfn.TEXTSPLIT(D29, "_"), 1), Sheet2!A$1:B$3, 2, FALSE)} -> 1
A30: 45674.62 | B30: NC25 | C30: 99 | D30: PW_BATHROOM-1 | E30: Andrew Jones | F30: Built surface | G30: 35°36′49″ N 82°19′12″ W | T30: Swab | V30: Women’s restroom right | AA30: Unknown | AB30: Sink | AC30: {=VLOOKUP(INDEX(_xlfn.TEXTSPLIT(D30, "_"), 1), Sheet2!A$1:B$3, 2, FALSE)} -> 1
A31: 45674.62 | B31: NC25 | C31: 100 | D31: PW_BATHROOM-2 | E31: Andrew Jones | F31: Built surface | G31: 35°36′49″ N 82°19′12″ W | T31: Swab | V31: Women’s restroom left | AA31: Unknown | AB31: Sink | AC31: {=VLOOKUP(INDEX(_xlfn.TEXTSPLIT(D31, "_"), 1), Sheet2!A$1:B$3, 2, FALSE)} -> 1
A32: 45674.77 | B32: NC25 | C32: 101 | D32: PW_WOOD_DRY-1 | E32: Vesper Fraunfelter | F32: Built surface | G32: 35°36′47.2″N, 82°19′15.4″W | T32: Swab | U32: 10 | V32: Unflooded wood stud | AA32: Wood | AB32: Sink | AC32: {=VLOOKUP(INDEX(_xlfn.TEXTSPLIT(D32, "_"), 1), Sheet2!A$1:B$3, 2, FALSE)} -> 1
A33: 45674.771 | B33: NC25 | C33: 102 | D33: PW_DRYWALL_DRY-1 | E33: Vesper Fraunfelter | F33: Built surface | G33: 35°36′47.2″N, 82°19′15.4″W | T33: Swab | U33: 10 | V33: Unflooded drywall | AA33: Drywall | AB33: Sink | AC33: {=VLOOKUP(INDEX(_xlfn.TEXTSPLIT(D33, "_"), 1), Sheet2!A$1:B$3, 2, FALSE)} -> 1
A34: 45674.776 | B34: NC25 | C34: 103 | D34: PW_PVC_WATERLINE-1 | E34: Vesper Fraunfelter | F34: Built surface | G34: 35°36′48″ N 82°19′14″ W | T34: Swab | V34: PVC water line with caked on mud | AA34: Plastic | AB34: Sink | AC34: {=VLOOKUP(INDEX(_xlfn.TEXTSPLIT(D34, "_"), 1), Sheet2!A$1:B$3, 2, FALSE)} -> 1
A35: 45674.626 | B35: NC25 | C35: 104 | D35: PW_KTCH_DRAIN_INNER-1 | E35: Andrew Jones | F35: Built surface | G35: 35°36′47″ N 82°19′12″ W | T35: Swab | V35: Kitchen inner drain | AA35: Metal | AB35: Sink | AC35: {=VLOOKUP(INDEX(_xlfn.TEXTSPLIT(D35, "_"), 1), Sheet2!A$1:B$3, 2, FALSE)} -> 1
A36: 45674.628 | B36: NC25 | C36: 105 | D36: PW_KTCH_DRAIN_EXT-1 | E36: Andrew Jones | F36: Built surface | G36: 35°36′47″ N 82°19′12″ W | T36: Swab | V36: Kitchen sink exterior | AA36: Metal | AB36: Sink | AC36: {=VLOOKUP(INDEX(_xlfn.TEXTSPLIT(D36, "_"), 1), Sheet2!A$1:B$3, 2, FALSE)} -> 1
A37: 45674.637 | B37: NC25 | C37: 106 | D37: PW_DOOR-1 | E37: Andrew Jones | F37: Built surface | G37: 35°36′48″ N 82°19′14″ W | T37: Swab | U37: Rockey | V37: Removed door | AA37: Unknown | AB37: Sink | AC37: {=VLOOKUP(INDEX(_xlfn.TEXTSPLIT(D37, "_"), 1), Sheet2!A$1:B$3, 2, FALSE)} -> 1
A38: 45674.643 | B38: NC25 | C38: 107 | D38: PW_WALL_DRY-1 | E38: Andrew Jones | F38: Built surface | G38: 35°36′47″ N 82°19′12″ W | T38: Swab | V38: Stair wall | AA38: Drywall | AB38: Sink | AC38: {=VLOOKUP(INDEX(_xlfn.TEXTSPLIT(D38, "_"), 1), Sheet2!A$1:B$3, 2, FALSE)} -> 1
A39: 45674.699 | B39: NC25 | C39: 108 | D39: PW_GLASS_INT-1 | E39: Andrew Jones | F39: Built surface | G39: 35°37′26″ N 82°19′47″ W | T39: Swab | U39: Rockey | V39: Interior glass | AA39: Glass | AB39: Sink | AC39: {=VLOOKUP(INDEX(_xlfn.TEXTSPLIT(D39, "_"), 1), Sheet2!A$1:B$3, 2, FALSE)} -> 1
A40: 45674.639 | B40: NC25 | C40: 109 | D40: PW_GLASS_STORED-1 | E40: Andrew Jones | F40: Built surface | G40: 35°36′48″ N 82°19′14″ W | T40: Swab | U40: Rockey | V40: Stored glass | AA40: Glass | AB40: Sink | AC40: {=VLOOKUP(INDEX(_xlfn.TEXTSPLIT(D40, "_"), 1), Sheet2!A$1:B$3, 2, FALSE)} -> 1
A41: 45674.774 | B41: NC25 | C41: 110 | D41: PW_CEILINGTILE-1 | E41: Vesper Fraunfelter | F41: Built surface | G41: 35°36′47.7″N, 82°19′12.8″W | T41: Swab | U41: 10 | V41: Ceiling tile top (fiberglass product) | AA41: Fiberglass | AB41: Sink | AC41: {=VLOOKUP(INDEX(_xlfn.TEXTSPLIT(D41, "_"), 1), Sheet2!A$1:B$3, 2, FALSE)} -> 1
A42: 45674.777 | B42: NC25 | C42: 111 | D42: PW_CINDERBLOCK_FLOOD-1 | E42: Vesper Fraunfelter | F42: Built surface | G42: 35°36′47.2″N, 82°19′15.4″W | T42: Swab | U42: 10 | V42: Cinderblock (flooded) | AA42: Concrete | AB42: Sink | AC42: {=VLOOKUP(INDEX(_xlfn.TEXTSPLIT(D42, "_"), 1), Sheet2!A$1:B$3, 2, FALSE)} -> 1
A43: 45674.778 | B43: NC25 | C43: 112 | D43: PW_METAL_DRAIN_FLOOD-1 | E43: Vesper Fraunfelter | F43: Built surface | G43: 35°36′46.5″N, 82°19′15.4″W | T43: Swab | V43: Metal lid to drain pipe; inside of lid. Wet. | AA43: Metal | AB43: Sink | AC43: {=VLOOKUP(INDEX(_xlfn.TEXTSPLIT(D43, "_"), 1), Sheet2!A$1:B$3, 2, FALSE)} -> 1
...

Sheet Sheet2
A1: PW | B1: 1
A2: GLF | B2: 2
A3: VP | B3: 3
